{
  "skipped_validations_stores": {
    "database_store_backends": [],
    "unsupported": []
  },
  "skipped_docs_validations_stores": {
    "unsupported": []
  },
  "skipped_metrics_stores": {
    "database_store_backends": [],
    "unsupported": []
  },
  "exceptions": [
    {
      "site_name": "s3_site_broken",
      "src": "N/A",
      "dest": "N/A",
      "exception_message": "TypeError: \"expected string or bytes-like object\".  Traceback: \"Traceback (most recent call last):\n  File \"GE_PATH/cli/toolkit.py\", line 402, in load_data_context_with_error_handling\n    context = DataContext(directory)\n  File \"GE_PATH/data_context/data_context.py\", line 2121, in __init__\n    project_config = self._load_project_config()\n  File \"GE_PATH/data_context/data_context.py\", line 2157, in _load_project_config\n    return DataContextConfig.from_commented_map(config_dict)\n  File \"GE_PATH/data_context/types/base.py\", line 86, in from_commented_map\n    config = dataContextConfigSchema.load(commented_map)\n  File \"/Users/roblim/.ve/ge/lib/python3.6/site-packages/marshmallow/schema.py\", line 723, in load\n    data, many=many, partial=partial, unknown=unknown, postprocess=True\n  File \"/Users/roblim/.ve/ge/lib/python3.6/site-packages/marshmallow/schema.py\", line 886, in _do_load\n    field_errors=field_errors,\n  File \"/Users/roblim/.ve/ge/lib/python3.6/site-packages/marshmallow/schema.py\", line 1191, in _invoke_schema_validators\n    partial=partial,\n  File \"/Users/roblim/.ve/ge/lib/python3.6/site-packages/marshmallow/schema.py\", line 774, in _run_validator\n    validator_func(output, partial=partial, many=many)\n  File \"GE_PATH/data_context/types/base.py\", line 298, in validate_schema\n    data[\"config_version\"], MINIMUM_SUPPORTED_CONFIG_VERSION\ngreat_expectations.exceptions.UnsupportedConfigVersionError: You appear to have an invalid config version (1.0).\n    The version number must be at least 2. Please see the migration guide at https://docs.greatexpectations.io/en/latest/how_to_guides/migrating_versions.html\n\nDuring handling of the above exception, another exception occurred:\n\nTraceback (most recent call last):\n  File \"GE_PATH/cli/upgrade_helpers/upgrade_helper_v11.py\", line 195, in upgrade_store_backend\n    validation_source_keys = store_backend.list_keys()\n  File \"GE_PATH/data_context/store/tuple_store_backend.py\", line 432, in list_keys\n    s3_objects = s3.list_objects(Bucket=self.bucket, Prefix=self.prefix)\n  File \"/Users/roblim/.ve/ge/lib/python3.6/site-packages/botocore/client.py\", line 316, in _api_call\n    return self._make_api_call(operation_name, kwargs)\n  File \"/Users/roblim/.ve/ge/lib/python3.6/site-packages/botocore/client.py\", line 599, in _make_api_call\n    api_params, operation_model, context=request_context)\n  File \"/Users/roblim/.ve/ge/lib/python3.6/site-packages/botocore/client.py\", line 645, in _convert_to_request_dict\n    api_params, operation_model, context)\n  File \"/Users/roblim/.ve/ge/lib/python3.6/site-packages/botocore/client.py\", line 677, in _emit_api_params\n    params=api_params, model=operation_model, context=context)\n  File \"/Users/roblim/.ve/ge/lib/python3.6/site-packages/botocore/hooks.py\", line 356, in emit\n    return self._emitter.emit(aliased_event_name, **kwargs)\n  File \"/Users/roblim/.ve/ge/lib/python3.6/site-packages/botocore/hooks.py\", line 228, in emit\n    return self._emit(event_name, kwargs)\n  File \"/Users/roblim/.ve/ge/lib/python3.6/site-packages/botocore/hooks.py\", line 211, in _emit\n    response = handler(**kwargs)\n  File \"/Users/roblim/.ve/ge/lib/python3.6/site-packages/botocore/handlers.py\", line 223, in validate_bucket_name\n    if not VALID_BUCKET.search(bucket) and not VALID_S3_ARN.search(bucket):\nTypeError: expected string or bytes-like object\n\"."
    }
  ],
  "upgraded_validations_stores": {
    "validations_store": {
      "validations_updated": [
        {
          "src": "file://GE_PROJECT_DIR/uncommitted/validations/diabetic_data/warning/20200430T191246.763896Z/c3b4c5df224fef4b1a056a0f3b93aba5.json",
          "dest": "file://GE_PROJECT_DIR/uncommitted/validations/diabetic_data/warning/20200430T191246.763896Z/20200430T191246.763896Z/c3b4c5df224fef4b1a056a0f3b93aba5.json"
        }
      ],
      "exceptions": false
    }
  },
  "upgraded_docs_site_validations_stores": {
    "local_site": {
      "validation_result_pages_updated": [
        {
          "src": "file://GE_PROJECT_DIR/uncommitted/data_docs/local_site/validations/diabetic_data/warning/20200430T191246.763896Z/c3b4c5df224fef4b1a056a0f3b93aba5.html",
          "dest": "file://GE_PROJECT_DIR/uncommitted/data_docs/local_site/validations/diabetic_data/warning/20200430T191246.763896Z/20200430T191246.763896Z/c3b4c5df224fef4b1a056a0f3b93aba5.html"
        }
      ],
      "exceptions": false
    },
    "s3_site_broken": {
      "validation_result_pages_updated": [],
      "exceptions": true
    }
  }
}
